<sdf version='1.4'>
  <model name='irb4400'>
    <link name='base_link'>
      <pose>0 0 0 0 -0 0</pose>
      <inertial>
        <pose>-0.09014 0 0.10198 0 -0 0</pose>
        <mass>75.6961</mass>
        <inertia>
          <ixx>2.02159</ixx>
          <ixy>-2.45857e-06</ixy>
          <ixz>0.0721505</ixz>
          <iyy>3.96574</iyy>
          <iyz>-1.8955e-07</iyz>
          <izz>5.58001</izz>
        </inertia>
      </inertial>
      <collision name='base_link_collision_irb4400_link_1_base'>
        <pose>0 0 0.218 0 -0 0</pose>
        <geometry>
          <mesh>
            <scale>1 1 1</scale>
            <uri>model://irb4400_description/meshes/link1.STL</uri>
          </mesh>
        </geometry>
        <surface>
          <contact>
            <ode/>
          </contact>
          <friction>
            <ode/>
          </friction>
        </surface>
      </collision>
      <collision name='base_link_collision_the_wall'>
        <pose>1.5 0 1 0 -0 0</pose>
        <geometry>
          <box>
            <size>0.05 2 3.5</size>
          </box>
        </geometry>
      </collision>
      <visual name='base_link_visual_irb4400_link_1_base'>
        <pose>0 0 0.218 0 -0 0</pose>
        <geometry>
          <mesh>
            <scale>1 1 1</scale>
            <uri>model://irb4400_description/meshes/link1.STL</uri>
          </mesh>
        </geometry>
        <material>
          <script>
            <name>Gazebo/Orange</name>
            <uri>__default__</uri>
          </script>
        </material>
      </visual>
      <visual name='base_link_visual_the_wall'>
        <pose>1.5 0 1 0 -0 0</pose>
        <geometry>
          <box>
            <size>0.05 2 3.5</size>
          </box>
        </geometry>
      </visual>
      <gravity>1</gravity>
      <velocity_decay>
        <linear>0</linear>
        <angular>0</angular>
      </velocity_decay>
      <self_collide>0</self_collide>
    </link>
    <link name='irb4400_link_2_secondbase'>
      <pose>0 0 0.218 0 -0 0</pose>
      <inertial>
        <pose>-0.00843385 0.0266048 0.291384 0 -0 0</pose>
        <mass>118.298</mass>
        <inertia>
          <ixx>7.90107</ixx>
          <ixy>-0.57805</ixy>
          <ixz>1.99064</ixz>
          <iyy>8.08858</iyy>
          <iyz>-0.239697</iyz>
          <izz>10.0939</izz>
        </inertia>
      </inertial>
      <collision name='irb4400_link_2_secondbase_collision'>
        <pose>0 0 0 0 -0 0</pose>
        <geometry>
          <mesh>
            <scale>1 1 1</scale>
            <uri>model://irb4400_description/meshes/link2.STL</uri>
          </mesh>
        </geometry>
        <surface>
          <contact>
            <ode/>
          </contact>
          <friction>
            <ode/>
          </friction>
        </surface>
      </collision>
      <collision name='irb4400_link_2_secondbase_collision_irb4400_link_3_cylinder'>
        <pose>-0.47929 0.047 0.32047 0 -0.20909 0</pose>
        <geometry>
          <mesh>
            <scale>1 1 1</scale>
            <uri>model://irb4400_description/meshes/link3.STL</uri>
          </mesh>
        </geometry>
        <surface>
          <contact>
            <ode/>
          </contact>
          <friction>
            <ode/>
          </friction>
        </surface>
        <surface>
          <contact>
            <ode/>
          </contact>
          <friction>
            <ode/>
          </friction>
        </surface>
      </collision>
      <collision name='irb4400_link_2_secondbase_collision_irb4400_link_4_piston'>
        <pose>0.321696 0.047 0.490433 0 -0.20909 0</pose>
        <geometry>
          <mesh>
            <scale>1 1 1</scale>
            <uri>model://irb4400_description/meshes/link4.STL</uri>
          </mesh>
        </geometry>
        <surface>
          <contact>
            <ode/>
          </contact>
          <friction>
            <ode/>
          </friction>
        </surface>
        <surface>
          <contact>
            <ode/>
          </contact>
          <friction>
            <ode/>
          </friction>
        </surface>
      </collision>
      <visual name='irb4400_link_2_secondbase_visual'>
        <pose>0 0 0 0 -0 0</pose>
        <geometry>
          <mesh>
            <scale>1 1 1</scale>
            <uri>model://irb4400_description/meshes/link2.STL</uri>
          </mesh>
        </geometry>
        <material>
          <script>
            <name>Gazebo/Orange</name>
            <uri>__default__</uri>
          </script>
        </material>
      </visual>
      <visual name='irb4400_link_2_secondbase_visual_irb4400_link_3_cylinder'>
        <pose>-0.47929 0.047 0.32047 0 -0.20909 0</pose>
        <geometry>
          <mesh>
            <scale>1 1 1</scale>
            <uri>model://irb4400_description/meshes/link3.STL</uri>
          </mesh>
        </geometry>
        <material>
          <script>
            <name>Gazebo/Orange</name>
            <uri>__default__</uri>
          </script>
        </material>
      </visual>
      <visual name='irb4400_link_2_secondbase_visual_irb4400_link_4_piston'>
        <pose>0.321696 0.047 0.490433 0 -0.20909 0</pose>
        <geometry>
          <mesh>
            <scale>1 1 1</scale>
            <uri>model://irb4400_description/meshes/link4.STL</uri>
          </mesh>
        </geometry>
        <material>
          <script>
            <name>Gazebo/Orange</name>
            <uri>__default__</uri>
          </script>
        </material>
      </visual>
      <velocity_decay>
        <linear>0</linear>
        <angular>0</angular>
      </velocity_decay>
      <velocity_decay>
        <linear>0</linear>
        <angular>0</angular>
      </velocity_decay>
      <gravity>1</gravity>
      <velocity_decay>
        <linear>0</linear>
        <angular>0</angular>
      </velocity_decay>
      <self_collide>0</self_collide>
    </link>
    <joint name='irb4400_joint_1_2' type='revolute'>
      <child>irb4400_link_2_secondbase</child>
      <parent>base_link</parent>
      <axis>
        <xyz>0 0 1</xyz>
        <limit>
          <lower>-1</lower>
          <upper>1</upper>
          <effort>100000</effort>
          <velocity>2.62</velocity>
        </limit>
        <dynamics/>
      </axis>
    </joint>
    <link name='irb4400_link_7_mountarm_front'>
      <pose>0.2 -0.0835 0.68 0 -0 0</pose>
      <inertial>
        <pose>-0.156934 0.00328688 0.271134 0 -0 0</pose>
        <mass>53.4994</mass>
        <inertia>
          <ixx>6.24895</ixx>
          <ixy>-1.25972</ixy>
          <ixz>-2.17003</ixz>
          <iyy>9.68838</iyy>
          <iyz>-0.727644</iyz>
          <izz>6.06507</izz>
        </inertia>
      </inertial>
      <collision name='irb4400_link_7_mountarm_front_collision'>
        <pose>0 0 0 0 -0 0</pose>
        <geometry>
          <mesh>
            <scale>1 1 1</scale>
            <uri>model://irb4400_description/meshes/link7.STL</uri>
          </mesh>
        </geometry>
        <surface>
          <contact>
            <ode/>
          </contact>
          <friction>
            <ode/>
          </friction>
        </surface>
      </collision>
      <collision name='irb4400_link_7_mountarm_front_collision_irb4400_link_5_counterweight'>
        <pose>0 0 0 0 -0 0</pose>
        <geometry>
          <mesh>
            <scale>1 1 1</scale>
            <uri>model://irb4400_description/meshes/link5.STL</uri>
          </mesh>
        </geometry>
        <surface>
          <contact>
            <ode/>
          </contact>
          <friction>
            <ode/>
          </friction>
        </surface>
        <surface>
          <contact>
            <ode/>
          </contact>
          <friction>
            <ode/>
          </friction>
        </surface>
      </collision>
      <collision name='irb4400_link_7_mountarm_front_collision_irb4400_link_6_mountarm_back'>
        <pose>-0.3 0.005 0 0 -0 0</pose>
        <geometry>
          <mesh>
            <scale>1 1 1</scale>
            <uri>model://irb4400_description/meshes/link6.STL</uri>
          </mesh>
        </geometry>
        <surface>
          <contact>
            <ode/>
          </contact>
          <friction>
            <ode/>
          </friction>
        </surface>
        <surface>
          <contact>
            <ode/>
          </contact>
          <friction>
            <ode/>
          </friction>
        </surface>
      </collision>
      <visual name='irb4400_link_7_mountarm_front_visual'>
        <pose>0 0 0 0 -0 0</pose>
        <geometry>
          <mesh>
            <scale>1 1 1</scale>
            <uri>model://irb4400_description/meshes/link7.STL</uri>
          </mesh>
        </geometry>
        <material>
          <script>
            <name>Gazebo/Orange</name>
            <uri>__default__</uri>
          </script>
        </material>
      </visual>
      <visual name='irb4400_link_7_mountarm_front_visual_irb4400_link_5_counterweight'>
        <pose>0 0 0 0 -0 0</pose>
        <geometry>
          <mesh>
            <scale>1 1 1</scale>
            <uri>model://irb4400_description/meshes/link5.STL</uri>
          </mesh>
        </geometry>
        <material>
          <script>
            <name>Gazebo/Orange</name>
            <uri>__default__</uri>
          </script>
        </material>
      </visual>
      <visual name='irb4400_link_7_mountarm_front_visual_irb4400_link_6_mountarm_back'>
        <pose>-0.3 0.005 0 0 -0 0</pose>
        <geometry>
          <mesh>
            <scale>1 1 1</scale>
            <uri>model://irb4400_description/meshes/link6.STL</uri>
          </mesh>
        </geometry>
        <material>
          <script>
            <name>Gazebo/Orange</name>
            <uri>__default__</uri>
          </script>
        </material>
      </visual>
      <velocity_decay>
        <linear>0</linear>
        <angular>0</angular>
      </velocity_decay>
      <velocity_decay>
        <linear>0</linear>
        <angular>0</angular>
      </velocity_decay>
      <velocity_decay>
        <linear>0</linear>
        <angular>0</angular>
      </velocity_decay>
      <gravity>1</gravity>
      <velocity_decay>
        <linear>0</linear>
        <angular>0</angular>
      </velocity_decay>
      <self_collide>0</self_collide>
    </link>
    <joint name='irb4400_joint_2_7' type='revolute'>
      <child>irb4400_link_7_mountarm_front</child>
      <parent>irb4400_link_2_secondbase</parent>
      <axis>
        <xyz>0 1 0</xyz>
        <limit>
          <lower>-1.22</lower>
          <upper>1.66</upper>
          <effort>100000</effort>
          <velocity>2.09</velocity>
        </limit>
        <dynamics/>
      </axis>
    </joint>
    <link name='irb4400_link_8_armlink1'>
      <pose>0.2 -0.1525 1.57 0 -0 0</pose>
      <inertial>
        <pose>-0.12332 0.13239 0.13886 0 -0 0</pose>
        <mass>3.14152</mass>
        <inertia>
          <ixx>0.367514</ixx>
          <ixy>0.0167172</ixy>
          <ixz>-0.0338312</ixz>
          <iyy>1.28059</iyy>
          <iyz>0.0188677</iyz>
          <izz>1.30821</izz>
        </inertia>
      </inertial>
      <collision name='irb4400_link_8_armlink1_collision'>
        <pose>0 0 0 0 -0 0</pose>
        <geometry>
          <mesh>
            <scale>1 1 1</scale>
            <uri>model://irb4400_description/meshes/link8.STL</uri>
          </mesh>
        </geometry>
        <surface>
          <contact>
            <ode/>
          </contact>
          <friction>
            <ode/>
          </friction>
        </surface>
      </collision>
      <visual name='irb4400_link_8_armlink1_visual'>
        <pose>0 0 0 0 -0 0</pose>
        <geometry>
          <mesh>
            <scale>1 1 1</scale>
            <uri>model://irb4400_description/meshes/link8.STL</uri>
          </mesh>
        </geometry>
        <material>
          <script>
            <name>Gazebo/Orange</name>
            <uri>__default__</uri>
          </script>
        </material>
      </visual>
      <gravity>1</gravity>
      <velocity_decay>
        <linear>0</linear>
        <angular>0</angular>
      </velocity_decay>
      <self_collide>0</self_collide>
    </link>
    <joint name='irb4400_joint_7_8' type='revolute'>
      <child>irb4400_link_8_armlink1</child>
      <parent>irb4400_link_7_mountarm_front</parent>
      <axis>
        <xyz>0 1 0</xyz>
        <limit>
          <lower>-1.5</lower>
          <upper>1.13</upper>
          <effort>100000</effort>
          <velocity>2.09</velocity>
        </limit>
        <dynamics/>
      </axis>
    </joint>
    <link name='irb4400_link_9_armlink2'>
      <pose>0.4486 -2.77556e-17 1.72 0 -0 0</pose>
      <inertial>
        <pose>-0.41969 0.00412 -0.00114 0 -0 0</pose>
        <mass>16.9654</mass>
        <inertia>
          <ixx>0.0932262</ixx>
          <ixy>0.0136895</ixy>
          <ixz>0.000506548</ixz>
          <iyy>0.712908</iyy>
          <iyz>0.000157889</iyz>
          <izz>0.734534</izz>
        </inertia>
      </inertial>
      <collision name='irb4400_link_9_armlink2_collision'>
        <pose>0 0 0 0 -0 0</pose>
        <geometry>
          <mesh>
            <scale>1 1 1</scale>
            <uri>model://irb4400_description/meshes/link9.STL</uri>
          </mesh>
        </geometry>
        <surface>
          <contact>
            <ode/>
          </contact>
          <friction>
            <ode/>
          </friction>
        </surface>
      </collision>
      <visual name='irb4400_link_9_armlink2_visual'>
        <pose>0 0 0 0 -0 0</pose>
        <geometry>
          <mesh>
            <scale>1 1 1</scale>
            <uri>model://irb4400_description/meshes/link9.STL</uri>
          </mesh>
        </geometry>
        <material>
          <script>
            <name>Gazebo/Orange</name>
            <uri>__default__</uri>
          </script>
        </material>
      </visual>
      <gravity>1</gravity>
      <velocity_decay>
        <linear>0</linear>
        <angular>0</angular>
      </velocity_decay>
      <self_collide>0</self_collide>
    </link>
    <joint name='irb4400_joint_8_9' type='revolute'>
      <child>irb4400_link_9_armlink2</child>
      <parent>irb4400_link_8_armlink1</parent>
      <axis>
        <xyz>1 0 0</xyz>
        <limit>
          <lower>-3.49</lower>
          <upper>3.49</upper>
          <effort>100000</effort>
          <velocity>3.93</velocity>
        </limit>
        <dynamics/>
      </axis>
    </joint>
    <link name='irb4400_link_10_verticalrotor'>
      <pose>1.08 -0.03325 1.72 0 -0 0</pose>
      <inertial>
        <pose>-6e-05 0.03324 0 0 -0 0</pose>
        <mass>1.22576</mass>
        <inertia>
          <ixx>0.00246088</ixx>
          <ixy>-1.12756e-06</ixy>
          <ixz>-1.3e-10</ixz>
          <iyy>0.00465221</iyy>
          <iyz>0</iyz>
          <izz>0.00320698</izz>
        </inertia>
      </inertial>
      <collision name='irb4400_link_10_verticalrotor_collision'>
        <pose>0 0 0 0 -0 0</pose>
        <geometry>
          <mesh>
            <scale>1 1 1</scale>
            <uri>model://irb4400_description/meshes/link10.STL</uri>
          </mesh>
        </geometry>
        <surface>
          <contact>
            <ode/>
          </contact>
          <friction>
            <ode/>
          </friction>
        </surface>
      </collision>
      <visual name='irb4400_link_10_verticalrotor_visual'>
        <pose>0 0 0 0 -0 0</pose>
        <geometry>
          <mesh>
            <scale>1 1 1</scale>
            <uri>model://irb4400_description/meshes/link10.STL</uri>
          </mesh>
        </geometry>
        <material>
          <script>
            <name>Gazebo/Orange</name>
            <uri>__default__</uri>
          </script>
        </material>
      </visual>
      <gravity>1</gravity>
      <velocity_decay>
        <linear>0</linear>
        <angular>0</angular>
      </velocity_decay>
      <self_collide>0</self_collide>
    </link>
    <joint name='irb4400_joint_9_10' type='revolute'>
      <child>irb4400_link_10_verticalrotor</child>
      <parent>irb4400_link_9_armlink2</parent>
      <axis>
        <xyz>0 1 0</xyz>
        <limit>
          <lower>-2.09</lower>
          <upper>2.09</upper>
          <effort>100000</effort>
          <velocity>4.36</velocity>
        </limit>
        <dynamics/>
      </axis>
    </joint>
    <link name='irb4400_link_11_toolholder'>
      <pose>1.22 -2.77556e-17 1.72 0 -0 0</pose>
      <inertial>
        <pose>0.362656 0.000961511 0.350668 0 -0 0</pose>
        <mass>16.3148</mass>
        <inertia>
          <ixx>0.397288</ixx>
          <ixy>0.000799376</ixy>
          <ixz>-0.0641867</ixz>
          <iyy>0.507188</iyy>
          <iyz>0.000901149</iyz>
          <izz>0.136236</izz>
        </inertia>
      </inertial>
      <collision name='irb4400_link_11_toolholder_collision'>
        <pose>0 0 0 0 -0 0</pose>
        <geometry>
          <mesh>
            <scale>1 1 1</scale>
            <uri>model://irb4400_description/meshes/link11.STL</uri>
          </mesh>
        </geometry>
        <surface>
          <contact>
            <ode/>
          </contact>
          <friction>
            <ode/>
          </friction>
        </surface>
      </collision>
      <collision name='irb4400_link_11_toolholder_collision_irb4400_link_gripping_system'>
        <pose>0.100913 0 -0.39595 3.14159 -1.57079 3.14159</pose>
        <geometry>
          <mesh>
            <scale>1 1 1</scale>
            <uri>model://irb4400_description/meshes/gripping_system.STL</uri>
          </mesh>
        </geometry>
        <surface>
          <contact>
            <ode/>
          </contact>
          <friction>
            <ode/>
          </friction>
        </surface>
        <surface>
          <contact>
            <ode/>
          </contact>
          <friction>
            <ode/>
          </friction>
        </surface>
      </collision>
      <visual name='irb4400_link_11_toolholder_visual'>
        <pose>0 0 0 0 -0 0</pose>
        <geometry>
          <mesh>
            <scale>1 1 1</scale>
            <uri>model://irb4400_description/meshes/link11.STL</uri>
          </mesh>
        </geometry>
        <material>
          <script>
            <name>Gazebo/Orange</name>
            <uri>__default__</uri>
          </script>
        </material>
      </visual>
      <visual name='irb4400_link_11_toolholder_visual_irb4400_link_gripping_system'>
        <pose>0.100913 0 -0.39595 3.14159 -1.57079 3.14159</pose>
        <geometry>
          <mesh>
            <scale>1 1 1</scale>
            <uri>model://irb4400_description/meshes/gripping_system.STL</uri>
          </mesh>
        </geometry>
        <material>
          <script>
            <name>Gazebo/Orange</name>
            <uri>__default__</uri>
          </script>
        </material>
      </visual>
      <velocity_decay>
        <linear>0</linear>
        <angular>0</angular>
      </velocity_decay>
      <gravity>1</gravity>
      <velocity_decay>
        <linear>0</linear>
        <angular>0</angular>
      </velocity_decay>
      <self_collide>0</self_collide>
      <sensor name='link_gripping_system_contact_sensor' type='contact'>
        <always_on>1</always_on>
        <update_rate>5</update_rate>
        <contact>
          <collision>irb4400_link_11_toolholder_collision_irb4400_link_gripping_system</collision>
          <topic>/irb4400/contact_forces</topic>
        </contact>
        <plugin name='link_gripping_system_bumper' filename='libgazebo_ros_bumper.so'>
          <bumperTopicName>/irb4400/contact_forces</bumperTopicName>
          <frameName>irb4400_link_gripping_system</frameName>
        </plugin>
        <pose>0.0404565 0 0 0 -0 0</pose>
      </sensor>
    </link>
    <joint name='irb4400_joint_10_11' type='revolute'>
      <child>irb4400_link_11_toolholder</child>
      <parent>irb4400_link_10_verticalrotor</parent>
      <axis>
        <xyz>1 0 0</xyz>
        <limit>
          <lower>-6.98</lower>
          <upper>6.98</upper>
          <effort>100000</effort>
          <velocity>5.76</velocity>
        </limit>
        <dynamics/>
      </axis>
    </joint>
    <static>0</static>
    <plugin name='gazebo_ros_controller' filename='libgazebo_ros_control.so'>
      <robotNamespace>/irb4400</robotNamespace>
    </plugin>
  </model>
</sdf>
