<?xml version="1.0" ?>
<!-- =================================================================================== -->
<!-- |    This document was autogenerated by xacro from irb4400.urdf.xacro             | -->
<!-- |    EDITING THIS FILE BY HAND IS NOT RECOMMENDED                                 | -->
<!-- =================================================================================== -->
<robot name="irb4400" xmlns:xacro="http://www.ros.org/wiki/xacro">
  <material name="Black">
    <color rgba="0.0 0.0 0.0 1.0"/>
  </material>
  <material name="Blue">
    <color rgba="0.0 0.0 0.8 1.0"/>
  </material>
  <material name="Green">
    <color rgba="0.0 0.8 0.0 1.0"/>
  </material>
  <material name="Grey">
    <color rgba="0.5 0.5 0.5 1.0"/>
  </material>
  <material name="Light_Grey">
    <color rgba="0.8 0.8 0.8 1.0"/>
  </material>
  <material name="Ivory">
    <color rgba="1.0 1.0 0.94 1.0"/>
  </material>
  <material name="Orange">
    <color rgba="1.0 0.423529411765 0.0392156862745 1.0"/>
  </material>
  <material name="Brown">
    <color rgba="0.870588235294 0.811764705882 0.764705882353 1.0"/>
  </material>
  <material name="Red">
    <color rgba="0.8 0.0 0.0 1.0"/>
  </material>
  <material name="White">
    <color rgba="1.0 1.0 1.0 1.0"/>
  </material>
  <link name="base_link"/>
  <link name="the_wall">
    <visual>
      <origin rpy="0 0 0" xyz="0 0 0"/>
      <geometry>
        <box size="0.05 2 3.5"/>
      </geometry>
      <material name="LightGrey">
        <color rgba="0.75 0.75 0.75 1.0"/>
      </material>
    </visual>
    <collision>
      <origin rpy="0 0 0" xyz="0 0 0"/>
      <geometry>
        <box size="0.05 2 3.5"/>
      </geometry>
    </collision>
  </link>
  <link name="irb4400_link_1_base">
    <visual>
      <origin rpy="0 0 0" xyz="0 0 0"/>
      <geometry>
        <mesh filename="package://irb4400_description/meshes/link1.STL"/>
      </geometry>
      <material name="Orange"/>
    </visual>
    <collision>
      <origin rpy="0 0 0" xyz="0 0 0"/>
      <geometry>
        <mesh filename="package://irb4400_description/meshes/link1.STL"/>
      </geometry>
    </collision>
    <inertial>
      <origin rpy="0 0 0" xyz="-0.09014 0.00 -0.11602"/>
      <mass value="75.69606"/>
      <inertia ixx="2.02158864748" ixy="-0.00000245857" ixz="0.07215053239" iyy="3.96573960599" iyz="-0.00000018955" izz="5.58000931701"/>
    </inertial>
  </link>
  <link name="irb4400_link_2_secondbase">
    <visual>
      <origin rpy="0 0 0" xyz="0 0 0"/>
      <geometry>
        <mesh filename="package://irb4400_description/meshes/link2.STL"/>
      </geometry>
      <material name="Orange"/>
    </visual>
    <collision>
      <origin rpy="0 0 0" xyz="0 0 0"/>
      <geometry>
        <mesh filename="package://irb4400_description/meshes/link2.STL"/>
      </geometry>
    </collision>
    <inertial>
      <origin rpy="0 0 0" xyz="0.0231 0.02424 0.28312"/>
      <mass value="106.0064"/>
      <inertia ixx="7.76707391051" ixy="-0.65413192657" ixz="1.80808632391" iyy="6.55334982091" iyz="-0.21975875117" izz="8.63984458622"/>
    </inertial>
  </link>
  <link name="irb4400_link_3_cylinder">
    <visual>
      <origin rpy="0 0 0" xyz="0 0 0"/>
      <geometry>
        <mesh filename="package://irb4400_description/meshes/link3.STL"/>
      </geometry>
      <material name="Orange"/>
    </visual>
    <collision>
      <origin rpy="0 0 0" xyz="0 0 0"/>
      <geometry>
        <mesh filename="package://irb4400_description/meshes/link3.STL"/>
      </geometry>
    </collision>
    <inertial>
      <origin rpy="0 0 0" xyz="0.179 0.00 -0.00002"/>
      <mass value="11.53566"/>
      <inertia ixx="0.04074759034" ixy="0.00000000000" ixz="0.00004858592" iyy="0.30850932573" iyz="0.00" izz="0.30903668614"/>
    </inertial>
  </link>
  <link name="irb4400_link_4_piston">
    <visual>
      <origin rpy="0 0 0" xyz="0 0 0"/>
      <geometry>
        <mesh filename="package://irb4400_description/meshes/link4.STL"/>
      </geometry>
      <material name="Orange"/>
    </visual>
    <collision>
      <origin rpy="0 0 0" xyz="0 0 0"/>
      <geometry>
        <mesh filename="package://irb4400_description/meshes/link4.STL"/>
      </geometry>
    </collision>
    <inertial>
      <origin rpy="0 0 0" xyz="-0.24431 0.00 0.00"/>
      <mass value="0.75584"/>
      <inertia ixx="0.00019733407" ixy="0.00000000000" ixz="0.00" iyy="0.03156433794" iyz="0.00" izz="0.03148203319"/>
    </inertial>
  </link>
  <link name="irb4400_link_5_counterweight">
    <visual>
      <origin rpy="0 0 0" xyz="0 0 0"/>
      <geometry>
        <mesh filename="package://irb4400_description/meshes/link5.STL"/>
      </geometry>
      <material name="Orange"/>
    </visual>
    <collision>
      <origin rpy="0 0 0" xyz="0 0 0"/>
      <geometry>
        <mesh filename="package://irb4400_description/meshes/link5.STL"/>
      </geometry>
    </collision>
    <inertial>
      <origin rpy="0 0 0" xyz="-0.45632 -0.09644 0.03106"/>
      <mass value="19.39243"/>
      <inertia ixx="0.22343149172" ixy="0.11871670137" ixz="-0.00685091375" iyy="0.68945149758" iyz="-0.01963332363" izz="0.64664468298"/>
    </inertial>
  </link>
  <link name="irb4400_link_6_mountarm_back">
    <visual>
      <origin rpy="0 0 0" xyz="0 0 0"/>
      <geometry>
        <mesh filename="package://irb4400_description/meshes/link6.STL"/>
      </geometry>
      <material name="Orange"/>
    </visual>
    <collision>
      <origin rpy="0 0 0" xyz="0 0 0"/>
      <geometry>
        <mesh filename="package://irb4400_description/meshes/link6.STL"/>
      </geometry>
    </collision>
    <inertial>
      <origin rpy="0 0 0" xyz="-0.1777 -0.2234 0.46383"/>
      <mass value="3.12307"/>
      <inertia ixx="0.31945679899" ixy="0.00004669001" ixz="0.00538016881" iyy="0.32175995655" iyz="-0.00004947451" izz="0.00326582296"/>
    </inertial>
  </link>
  <link name="irb4400_link_6_auxiliary">
    <inertial>
      <origin rpy="0 0 0" xyz="0 0 0.89"/>
      <mass value="0.00"/>
      <inertia ixx="1" ixy="0" ixz="0" iyy="1" iyz="0" izz="1"/>
    </inertial>
  </link>
  <link name="irb4400_link_7_mountarm_front">
    <visual>
      <origin rpy="0 0 0" xyz="0 0 0"/>
      <geometry>
        <mesh filename="package://irb4400_description/meshes/link7.STL"/>
      </geometry>
      <material name="Orange"/>
    </visual>
    <collision>
      <origin rpy="0 0 0" xyz="0 0 0"/>
      <geometry>
        <mesh filename="package://irb4400_description/meshes/link7.STL"/>
      </geometry>
    </collision>
    <inertial>
      <origin rpy="0 0 0" xyz="0.06278 0.08805 0.40197"/>
      <mass value="30.98388"/>
      <inertia ixx="2.37305548407" ixy="-0.00037165355" ixz="-0.07708847390" iyy="2.35788846934" iyz="-0.03346985497" izz="0.29095169577"/>
    </inertial>
  </link>
  <link name="irb4400_link_8_armlink1">
    <visual>
      <origin rpy="0 0 0" xyz="0 0 0"/>
      <geometry>
        <mesh filename="package://irb4400_description/meshes/link8.STL"/>
      </geometry>
      <material name="Orange"/>
    </visual>
    <collision>
      <origin rpy="0 0 0" xyz="0 0 0"/>
      <geometry>
        <mesh filename="package://irb4400_description/meshes/link8.STL"/>
      </geometry>
    </collision>
    <inertial>
      <origin rpy="0 0 0" xyz="-0.12332 0.13239 0.13886"/>
      <mass value="3.141516"/>
      <inertia ixx="0.36751429290" ixy="0.01671715853" ixz="-0.03383121212" iyy="1.28059358192" iyz="0.01886768705" izz="1.30821199705"/>
    </inertial>
  </link>
  <link name="irb4400_link_9_armlink2">
    <visual>
      <origin rpy="0 0 0" xyz="0 0 0"/>
      <geometry>
        <mesh filename="package://irb4400_description/meshes/link9.STL"/>
      </geometry>
      <material name="Orange"/>
    </visual>
    <collision>
      <origin rpy="0 0 0" xyz="0 0 0"/>
      <geometry>
        <mesh filename="package://irb4400_description/meshes/link9.STL"/>
      </geometry>
    </collision>
    <inertial>
      <origin rpy="0 0 0" xyz="-0.41969 0.00412 -0.00114"/>
      <mass value="16.9654"/>
      <inertia ixx="0.09322623509" ixy="0.01368950722" ixz="0.00050654774" iyy="0.71290847900" iyz="0.00015788926" izz="0.73453378938"/>
    </inertial>
  </link>
  <link name="irb4400_link_10_verticalrotor">
    <visual>
      <origin rpy="0 0 0" xyz="0 0 0"/>
      <geometry>
        <mesh filename="package://irb4400_description/meshes/link10.STL"/>
      </geometry>
      <material name="Orange"/>
    </visual>
    <collision>
      <origin rpy="0 0 0" xyz="0 0 0"/>
      <geometry>
        <mesh filename="package://irb4400_description/meshes/link10.STL"/>
      </geometry>
    </collision>
    <inertial>
      <origin rpy="0 0 0" xyz="-0.00006 0.03324 0.00"/>
      <mass value="1.22576"/>
      <inertia ixx="0.00246087716" ixy="-0.00000112756" ixz="-0.00000000013" iyy="0.00465221441" iyz="0.00" izz="0.00320698422"/>
    </inertial>
  </link>
  <link name="irb4400_link_11_toolholder">
    <visual>
      <origin rpy="0 0 0" xyz="0 0 0"/>
      <geometry>
        <mesh filename="package://irb4400_description/meshes/link11.STL"/>
      </geometry>
      <material name="Orange"/>
    </visual>
    <collision>
      <origin rpy="0 0 0" xyz="0 0 0"/>
      <geometry>
        <mesh filename="package://irb4400_description/meshes/link11.STL"/>
      </geometry>
    </collision>
    <inertial>
      <origin rpy="0 0 0" xyz="-0.06688 0.00 -0.00006"/>
      <mass value="0.42133"/>
      <inertia ixx="0.00038671431" ixy="0.00000000000" ixz="-0.00000145510" iyy="0.00192619966" iyz="0.00" izz="0.00192737654"/>
    </inertial>
  </link>
  <link name="irb4400_link_gripping_system">
    <visual>
      <origin rpy="0 -1.57079632679 0" xyz="0.0604565 0 -0.39595"/>
      <geometry>
        <mesh filename="package://irb4400_description/meshes/gripping_system.STL"/>
      </geometry>
      <material name="DarkGreen">
        <color rgba="0.15 0.35 0.0 1.0"/>
      </material>
    </visual>
    <collision name="irb4400_link_11_toolholder_collision_irb4400_link_gripping_system">
      <origin rpy="0 -1.57079632679 0" xyz="0.0604565 0 -0.39595"/>
      <geometry>
        <mesh filename="package://irb4400_description/meshes/gripping_system.STL"/>
      </geometry>
    </collision>
    <inertial>
      <!-- center of mass in STL files frame: (0.394043, 0.000987, -0.035984) -->
      <origin rpy="0 1.57079632679 0" xyz="0.3335865 0.000987 0.359966"/>
      <mass value="15.893435"/>
      <inertia ixx="0.054512" ixy="-0.001047" ixz="-0.000971" iyy="0.372263" iyz="0.000978" izz="0.343699"/>
    </inertial>
  </link>
  <!--link name="irb4400_link_rebar">
    <visual>
      <origin rpy="1.57079632679 0 0" xyz="0 0 0"/>
      <geometry>
        <mesh filename="package://irb4400_description/meshes/rebar.STL"/>
      </geometry>
      <material name="Grey"/>
    </visual>
    <collision>
       <origin rpy="1.57079632679 0 0" xyz="0 0 0"></origin>
       <geometry>
          <mesh filename="package://irb4400_description/meshes/rebar.STL"></mesh>
       </geometry>
    </collision>
    <inertial>
      <origin rpy="1.57079632679 0 0" xyz="0 0 0"/>
      <mass value="18.8194"/>
      <inertia ixx="0.01411575191543" ixy="0.00"             ixz="0.00" 
                                      iyy="0.00000240888277" iyz="0.00" 
                                                             izz="0.01411575191543"/>
    </inertial>
  </link-->
  <joint name="joint_wall_to_world" type="fixed">
    <parent link="base_link"/>
    <child link="the_wall"/>
    <origin xyz="1.5 0 1"/>
  </joint>
  <joint name="irb4400_joint_base_to_baselink" type="fixed">
    <parent link="base_link"/>
    <child link="irb4400_link_1_base"/>
    <origin xyz="0 0 0.218"/>
  </joint>
  <joint name="irb4400_joint_1_2" type="revolute">
    <parent link="irb4400_link_1_base"/>
    <child link="irb4400_link_2_secondbase"/>
    <!--limit effort="100000.0" lower="-2.88" upper="2.88" velocity="2.62"/-->
    <limit effort="100000.0" lower="-1.0" upper="1.0" velocity="2.62"/>
    <axis xyz="0 0 1"/>
    <origin xyz="0 0 0"/>
  </joint>
  <!--joint name="irb4400_joint_2_3" type="revolute">
    <parent link="irb4400_link_2_secondbase"/>
    <child link="irb4400_link_3_cylinder"/>
    <limit effort="1000.0" lower="-3.14" upper="3.14" velocity="1000"/>
    <axis xyz="0 1 0"/>
    <origin xyz="-0.47929 0.047 0.32047" rpy="0 -0.20909044 0"/>
  </joint-->
  <joint name="irb4400_joint_2_3" type="fixed">
    <parent link="irb4400_link_2_secondbase"/>
    <child link="irb4400_link_3_cylinder"/>
    <origin rpy="0 -0.20909044 0" xyz="-0.47929 0.047 0.32047"/>
  </joint>
  <!--joint name="irb4400_joint_3_4" type="prismatic">
    <parent link="irb4400_link_3_cylinder"/>
    <child link="irb4400_link_4_piston"/>
    <limit effort="1000.0" lower="-0.5" upper="0.1" velocity="1000"/>
    <axis xyz="1 0 0"/>
    <origin xyz="0.81882 0.00 0.00"/>
  </joint-->
  <joint name="irb4400_joint_3_4" type="fixed">
    <parent link="irb4400_link_3_cylinder"/>
    <child link="irb4400_link_4_piston"/>
    <origin xyz="0.81882 0.00 0.00"/>
  </joint>
  <joint name="irb4400_joint_2_7" type="revolute">
    <parent link="irb4400_link_2_secondbase"/>
    <child link="irb4400_link_7_mountarm_front"/>
    <limit effort="100000.0" lower="-1.22" upper="1.66" velocity="2.09"/>
    <axis xyz="0 1 0"/>
    <origin xyz="0.2 -0.0835 0.462"/>
  </joint>
  <!--joint name="irb4400_joint_7_5" type="revolute">
    <parent link="irb4400_link_7_mountarm_front"/>
    <child link="irb4400_link_5_counterweight"/>
    <limit effort="1000.0" lower="-3.14" upper="3.14" velocity="1000"/>
    <axis xyz="0 1 0"/>
    <origin xyz="0 0 0"/>
  </joint-->
  <joint name="irb4400_joint_7_5" type="fixed">
    <parent link="irb4400_link_7_mountarm_front"/>
    <child link="irb4400_link_5_counterweight"/>
    <origin xyz="0 0 0"/>
  </joint>
  <!--joint name="irb4400_joint_5_6" type="revolute">
    <parent link="irb4400_link_5_counterweight"/>
    <child link="irb4400_link_6_mountarm_back"/>
    <limit effort="1000.0" lower="-3.14" upper="3.14" velocity="1000"/>
    <axis xyz="0 1 0"/>
    <origin xyz="-0.3 0.005 0.00"/>
  </joint-->
  <joint name="irb4400_joint_5_6" type="fixed">
    <parent link="irb4400_link_5_counterweight"/>
    <child link="irb4400_link_6_mountarm_back"/>
    <origin xyz="-0.3 0.005 0.00"/>
  </joint>
  <joint name="irb4400_joint_6_6aux" type="fixed">
    <parent link="irb4400_link_6_mountarm_back"/>
    <child link="irb4400_link_6_auxiliary"/>
    <axis xyz="0 0 0"/>
    <origin xyz="0.0 0.0 0.89"/>
  </joint>
  <joint name="irb4400_joint_7_8" type="revolute">
    <parent link="irb4400_link_7_mountarm_front"/>
    <child link="irb4400_link_8_armlink1"/>
    <limit effort="100000.0" lower="-1.5" upper="1.13" velocity="2.09"/>
    <axis xyz="0 1 0"/>
    <origin xyz="0.0 -0.069 0.89"/>
  </joint>
  <joint name="irb4400_joint_8_9" type="revolute">
    <parent link="irb4400_link_8_armlink1"/>
    <child link="irb4400_link_9_armlink2"/>
    <limit effort="100000.0" lower="-3.49" upper="3.49" velocity="3.93"/>
    <axis xyz="1 0 0"/>
    <origin xyz="0.2486 0.1525 0.15"/>
  </joint>
  <joint name="irb4400_joint_9_10" type="revolute">
    <parent link="irb4400_link_9_armlink2"/>
    <child link="irb4400_link_10_verticalrotor"/>
    <limit effort="100000.0" lower="-2.09" upper="2.09" velocity="4.36"/>
    <axis xyz="0 1 0"/>
    <origin xyz="0.6314 -0.03325 0.00"/>
  </joint>
  <joint name="irb4400_joint_10_11" type="revolute">
    <parent link="irb4400_link_10_verticalrotor"/>
    <child link="irb4400_link_11_toolholder"/>
    <limit effort="100000.0" lower="-6.98" upper="6.98" velocity="5.76"/>
    <axis xyz="1 0 0"/>
    <origin xyz="0.14 0.03325 0.00"/>
  </joint>
  <joint name="irb4400_joint_11_gripping_system" type="fixed">
    <parent link="irb4400_link_11_toolholder"/>
    <child link="irb4400_link_gripping_system"/>
    <origin xyz="0.0404565 0.00 0.00"/>
  </joint>
  <!--joint name="irb4400_joint_gripping_system_rebar" type="fixed">
    <parent link="irb4400_link_gripping_system"/>
    <child link="irb4400_link_rebar"/>
    <origin xyz="0.18 0.00 0.00"/>
  </joint-->
  <gazebo>
    <plugin filename="libgazebo_ros_control.so" name="gazebo_ros_controller">
      <robotNamespace>/irb4400</robotNamespace>
    </plugin>
    <!--joint name="irb4400_joint_7_4" type="revolute">
      <parent>irb4400_link_7_mountarm_front</parent>
      <child>irb4400_link_4_piston</child>
      <axis>
        <xyz>0 1 0</xyz>
      </axis>
      <pose>0.1217 0.1305 0.0284 0 0 0</pose>
    </joint-->
    <!--joint name="irb4400_joint_8_6aux" type="revolute">
      <parent>irb4400_link_8_armlink1</parent>
      <child>irb4400_link_6_auxiliary</child>
      <axis>
        <xyz>0 1 0</xyz>
      </axis>
      <pose>-0.3 0.074 0.00 0 0 0</pose>
    </joint-->
  </gazebo>
  <gazebo reference="irb4400_link_1_base">
    <material>Gazebo/Orange</material>
  </gazebo>
  <gazebo reference="irb4400_link_2_secondbase">
    <material>Gazebo/Orange</material>
  </gazebo>
  <gazebo reference="irb4400_link_3_cylinder">
    <material>Gazebo/Orange</material>
  </gazebo>
  <gazebo reference="irb4400_link_4_piston">
    <material>Gazebo/Orange</material>
  </gazebo>
  <gazebo reference="irb4400_link_5_counterweight">
    <material>Gazebo/Orange</material>
  </gazebo>
  <gazebo reference="irb4400_link_6_mountarm_back">
    <material>Gazebo/Orange</material>
  </gazebo>
  <gazebo reference="irb4400_link_6_auxiliary">
    <material>Gazebo/Orange</material>
  </gazebo>
  <gazebo reference="irb4400_link_7_mountarm_front">
    <material>Gazebo/Orange</material>
  </gazebo>
  <gazebo reference="irb4400_link_8_armlink1">
    <material>Gazebo/Orange</material>
  </gazebo>
  <gazebo reference="irb4400_link_9_armlink2">
    <material>Gazebo/Orange</material>
  </gazebo>
  <gazebo reference="irb4400_link_10_verticalrotor">
    <material>Gazebo/Orange</material>
  </gazebo>
  <gazebo reference="irb4400_link_11_toolholder">
    <material>Gazebo/Orange</material>
  </gazebo>
  <gazebo reference="irb4400_link_gripping_system">
    <material>Gazebo/Orange</material>
    <sensor name="link_gripping_system_contact_sensor" type="contact">
      <always_on>true</always_on>
      <update_rate>5</update_rate>
      <contact>
        <collision>irb4400_link_11_toolholder_collision_irb4400_link_gripping_system</collision>
        <topic>/irb4400/contact_forces</topic>
      </contact>
      <plugin filename="libgazebo_ros_bumper.so" name="link_gripping_system_bumper">
        <bumperTopicName>/irb4400/contact_forces</bumperTopicName>
        <frameName>irb4400_link_gripping_system</frameName>
      </plugin>
    </sensor>
  </gazebo>
  <transmission name="irb4400_transmission_1">
    <type>transmission_interface/SimpleTransmission</type>
    <joint name="irb4400_joint_1_2">
      <hardwareInterface>VelocityJointInterface</hardwareInterface>
    </joint>
    <actuator name="irb4400_motor_1">
      <hardwareInterface>VelocityJointInterface</hardwareInterface>
      <mechanicalReduction>1</mechanicalReduction>
    </actuator>
  </transmission>
  <transmission name="irb4400_transmission_2">
    <type>transmission_interface/SimpleTransmission</type>
    <joint name="irb4400_joint_2_7">
      <hardwareInterface>VelocityJointInterface</hardwareInterface>
    </joint>
    <actuator name="irb4400_motor_2">
      <hardwareInterface>VelocityJointInterface</hardwareInterface>
      <mechanicalReduction>1</mechanicalReduction>
    </actuator>
  </transmission>
  <transmission name="irb4400_transmission_3">
    <type>transmission_interface/SimpleTransmission</type>
    <joint name="irb4400_joint_7_8">
      <hardwareInterface>VelocityJointInterface</hardwareInterface>
    </joint>
    <actuator name="irb4400_motor_3">
      <hardwareInterface>VelocityJointInterface</hardwareInterface>
      <mechanicalReduction>1</mechanicalReduction>
    </actuator>
  </transmission>
  <transmission name="irb4400_transmission_4">
    <type>transmission_interface/SimpleTransmission</type>
    <joint name="irb4400_joint_8_9">
      <hardwareInterface>VelocityJointInterface</hardwareInterface>
    </joint>
    <actuator name="irb4400_motor_4">
      <hardwareInterface>VelocityJointInterface</hardwareInterface>
      <mechanicalReduction>1</mechanicalReduction>
    </actuator>
  </transmission>
  <transmission name="irb4400_transmission_5">
    <type>transmission_interface/SimpleTransmission</type>
    <joint name="irb4400_joint_9_10">
      <hardwareInterface>VelocityJointInterface</hardwareInterface>
    </joint>
    <actuator name="irb4400_motor_5">
      <hardwareInterface>VelocityJointInterface</hardwareInterface>
      <mechanicalReduction>1</mechanicalReduction>
    </actuator>
  </transmission>
  <transmission name="irb4400_transmission_6">
    <type>transmission_interface/SimpleTransmission</type>
    <joint name="irb4400_joint_10_11">
      <hardwareInterface>VelocityJointInterface</hardwareInterface>
    </joint>
    <actuator name="irb4400_motor_6">
      <hardwareInterface>VelocityJointInterface</hardwareInterface>
      <mechanicalReduction>1</mechanicalReduction>
    </actuator>
  </transmission>
  <!--transmission name="irb4400_transmission_56">
      <type>transmission_interface/SimpleTransmission</type>
      <joint name="irb4400_joint_5_6">
        <hardwareInterface>${hardware_interface}</hardwareInterface>
      </joint>
      <actuator name="irb4400_motor_56">
        <hardwareInterface>${hardware_interface}</hardwareInterface>
        <mechanicalReduction>1</mechanicalReduction>
      </actuator>
    </transmission-->
</robot>

