<?xml version="1.0"?>

<robot name="irb4400" xmlns:xacro="http://ros.org/wiki/xacro">

  <joint name="joint_wall_to_world" type="fixed">
    <parent link="base_link"/>
    <child link="the_wall"/>
    <origin xyz="1.5 0 1"/>
  </joint>





  <joint name="irb4400_joint_base_to_baselink" type="fixed">
    <parent link="base_link"/>
    <child link="irb4400_link_1_base"/>
    <origin xyz="0 0 0.218"/>
  </joint>

  <joint name="irb4400_joint_1_2" type="revolute">
    <parent link="irb4400_link_1_base"/>
    <child link="irb4400_link_2_secondbase"/>
    <!--limit effort="100000.0" lower="-2.88" upper="2.88" velocity="2.62"/-->
    <limit effort="100000.0" lower="-1.0" upper="1.0" velocity="2.62"/>
    <axis xyz="0 0 1"/>
    <origin xyz="0 0 0"/>
  </joint>

  <!--joint name="irb4400_joint_2_3" type="revolute">
    <parent link="irb4400_link_2_secondbase"/>
    <child link="irb4400_link_3_cylinder"/>
    <limit effort="1000.0" lower="-3.14" upper="3.14" velocity="1000"/>
    <axis xyz="0 1 0"/>
    <origin xyz="-0.47929 0.047 0.32047" rpy="0 -0.20909044 0"/>
  </joint-->

  <joint name="irb4400_joint_2_3" type="fixed">
    <parent link="irb4400_link_2_secondbase"/>
    <child link="irb4400_link_3_cylinder"/>
    <origin xyz="-0.47929 0.047 0.32047" rpy="0 -0.20909044 0"/>
  </joint>

  <!--joint name="irb4400_joint_3_4" type="prismatic">
    <parent link="irb4400_link_3_cylinder"/>
    <child link="irb4400_link_4_piston"/>
    <limit effort="1000.0" lower="-0.5" upper="0.1" velocity="1000"/>
    <axis xyz="1 0 0"/>
    <origin xyz="0.81882 0.00 0.00"/>
  </joint-->

  <joint name="irb4400_joint_3_4" type="fixed">
    <parent link="irb4400_link_3_cylinder"/>
    <child link="irb4400_link_4_piston"/>
    <origin xyz="0.81882 0.00 0.00"/>
  </joint>

  <joint name="irb4400_joint_2_7" type="revolute">
    <parent link="irb4400_link_2_secondbase"/>
    <child link="irb4400_link_7_mountarm_front"/>
    <limit effort="100000.0" lower="-1.22" upper="1.66" velocity="2.09"/>
    <axis xyz="0 1 0"/>
    <origin xyz="0.2 -0.0835 0.462"/>
  </joint>

  <!--joint name="irb4400_joint_7_5" type="revolute">
    <parent link="irb4400_link_7_mountarm_front"/>
    <child link="irb4400_link_5_counterweight"/>
    <limit effort="1000.0" lower="-3.14" upper="3.14" velocity="1000"/>
    <axis xyz="0 1 0"/>
    <origin xyz="0 0 0"/>
  </joint-->

  <joint name="irb4400_joint_7_5" type="fixed">
    <parent link="irb4400_link_7_mountarm_front"/>
    <child link="irb4400_link_5_counterweight"/>
    <origin xyz="0 0 0"/>
  </joint>

  <!--joint name="irb4400_joint_5_6" type="revolute">
    <parent link="irb4400_link_5_counterweight"/>
    <child link="irb4400_link_6_mountarm_back"/>
    <limit effort="1000.0" lower="-3.14" upper="3.14" velocity="1000"/>
    <axis xyz="0 1 0"/>
    <origin xyz="-0.3 0.005 0.00"/>
  </joint-->

  <joint name="irb4400_joint_5_6" type="fixed">
    <parent link="irb4400_link_5_counterweight"/>
    <child link="irb4400_link_6_mountarm_back"/>
    <origin xyz="-0.3 0.005 0.00"/>
  </joint>

  <joint name="irb4400_joint_6_6aux" type="fixed">
    <parent link="irb4400_link_6_mountarm_back"/>
    <child link="irb4400_link_6_auxiliary"/>
    <axis xyz="0 0 0"/>
    <origin xyz="0.0 0.0 0.89"/>
  </joint>
  
  <joint name="irb4400_joint_7_8" type="revolute">
    <parent link="irb4400_link_7_mountarm_front"/>
    <child link="irb4400_link_8_armlink1"/>
    <limit effort="100000.0" lower="-1.5" upper="1.13" velocity="2.09"/>
    <axis xyz="0 1 0"/>
    <origin xyz="0.0 -0.069 0.89"/>
  </joint>
  
  <joint name="irb4400_joint_8_9" type="revolute">
    <parent link="irb4400_link_8_armlink1"/>
    <child link="irb4400_link_9_armlink2"/>
    <limit effort="100000.0" lower="-3.49" upper="3.49" velocity="3.93"/>
    <axis xyz="1 0 0"/>
    <origin xyz="0.2486 0.1525 0.15"/>
  </joint>

  <joint name="irb4400_joint_9_10" type="revolute">
    <parent link="irb4400_link_9_armlink2"/>
    <child link="irb4400_link_10_verticalrotor"/>
    <limit effort="100000.0" lower="-2.09" upper="2.09" velocity="4.36"/>
    <axis xyz="0 1 0"/>
    <origin xyz="0.6314 -0.03325 0.00"/>
  </joint>

  <joint name="irb4400_joint_10_11" type="revolute">
    <parent link="irb4400_link_10_verticalrotor"/>
    <child link="irb4400_link_11_toolholder"/>
    <limit effort="100000.0" lower="-6.98" upper="6.98" velocity="5.76"/>
    <axis xyz="1 0 0"/>
    <origin xyz="0.14 0.03325 0.00"/>
  </joint>

  <joint name="irb4400_joint_11_gripping_system" type="fixed">
    <parent link="irb4400_link_11_toolholder"/>
    <child link="irb4400_link_gripping_system"/>
    <origin xyz="0.0404565 0.00 0.00"/>
  </joint>

  <!--joint name="irb4400_joint_gripping_system_rebar" type="fixed">
    <parent link="irb4400_link_gripping_system"/>
    <child link="irb4400_link_rebar"/>
    <origin xyz="0.18 0.00 0.00"/>
  </joint-->

</robot>
