    THESE JOINTS CREATE CYCLES IN THE URDF TREE AND ARE THEREFORE OMITTED
    THESE JOINTS ARE INSTEAD ADDED USING THE <gazebo> TAG!
    // marcus

    <joint name="joint4_7" type="revolute">
      <parent>link4</parent>
      <child>link7</child>
      <pose>0.1217 0.1305 0.0284 0 0 0</pose>
      <axis>
        <xyz>0 1 0</xyz>
      </axis>
      <limit>
        <effort>1000.0</effort>
        <lower>-0.5</lower>
        <upper>0.1</upper>
        <velocity>0.5</velocity>
      </limit>
    </joint>

    <joint name="joint6_8" type="revolute">
      <parent>link6</parent>
      <child>link8</child>
      <pose>0.3 0.074 0.89 0 0 0</pose>
      <axis>
        <xyz>0 1 0</xyz>
      </axis>
      <limit>
        <effort>1000.0</effort>
        <lower>-0.5</lower>
        <upper>0.1</upper>
        <velocity>0.5</velocity>
      </limit>
    </joint>